Workbook
Name p: 'Cost Summary'!$B$21
Name Costing_Sheet_Multiple_Location.2023.xlsx: 'Cost Summary'!$B$21
Name Costing_Sheet_Multiple_Location.2023.xlsx: 'Cost Summary'!$B$21
Name Costing_Sheet_Multiple_Location.2023.xlsx: 'Cost Summary'!$B$21
Name Costing_Sheet_Multiple_Location.2023.xlsx: 'Cost Summary'!$B$21
Name Costing_Sheet_Multiple_Location.2023.xlsx: 'Cost Summary'!$B$21
Name Costing_Sheet_Multiple_Location.2023.xlsx: 'Cost Summary'!$B$21
Name Costing_Sheet_Multiple_Location.2023.xlsx: 'Cost Summary'!$B$21

Sheet Cost Summary
A1: Customer and Project Scope -
A3: AINSWORTH LABOUR
A4: Item | B4: Task | C4: # of techs | D4: Days | E4: Hours | F4: Total Hours | G4: COST | H4: Subtotal 1 | I4: Margin | J4: Subtotal 2
A5: Project Management
A6: 1 | B6: Engineering/Meetings | C6: 0 | D6: 0 | F6: =C6*D6*E6 | G6: 90 | H6: =F6*G6 | I6: 0.85 | J6: =H6/I6
A7: 2 | B7: Project Management | C7: 0.05 | D7: 1 | E7: 1 | F7: =C7*D7*E7 | G7: =J6+J8+J9+J10+J11+J12+J16+J27+J32 | H7: =F7*G7 | I7: 0.85 | J7: =H7/I7
A8: 3 | B8: ESA Submissions | F8: =C8*D8*E8 | G8: 2000 | H8: =F8*G8 | I8: 0.85 | J8: =H8/I8
A9: 4 | B9: Misc. Subcontractors | C9: 0.05 | D9: 1 | E9: 1 | F9: =C9*D9*E9 | G9: ='Location 1'!P37+'Location 2'!P33+'Location 3'!P36+'Location 4'!P36+'Location 5'!P36+'Location 6'!P36+'Option 1'!P36 | H9: =F9*G9 | I9: 0.85 | J9: =H9/I9
A10: 5 | B10: Misc. Materials | C10: 0.05 | D10: 1 | E10: 1 | F10: =C10*D10*E10 | G10: ='Location 1'!P42+'Location 2'!P44+'Location 3'!P62+'Location 4'!P62+'Location 5'!P62+'Location 6'!P62+'Option 1'!P62 | H10: =F10*G10 | I10: 0.85 | J10: =H10/I10
A11: 6 | B11: Health and Safety | F11: =C11*D11*E11 | G11: 80 | H11: =F11*G11 | I11: 0.85 | J11: =H11/I11
A12: 7 | B12: Lodging | F12: =C12*D12*E12 | H12: =F12*G12 | I12: 0.85 | J12: =H12/I12
A13: Total Management | F13: =SUM(F6:F12) | H13: =SUM(H6:H12) | J13: =SUM(J6:J12)
A15: Labour
A16: 1 | B16: Other | F16: =C16*D16*E16 | H16: =F16*G16 | I16: 0.85 | J16: =H16/I16
A17: Sub Total Labour | F17: =SUM(F16:F16) | H17: =SUM(H16:H16) | J17: =SUM(J16:J16)
A18: Subtotal Labour | F18: =F13+F17 | H18: =H13+H17 | J18: =J13+J17
A19: Sheet Cost Summary
A20: Item | B20: Task | C20: Surcharge | D20: Days/Units | E20: Other | F20: Total Surcharge | G20: Unit Price | H20: Subtotal 1 | I20: Margin | J20: Subtotal 2
A21: 1 | B21: ='Location 1'!R1 | C21: 1 | D21: 1 | E21: 1 | F21: =C21*D21*E21 | G21: ='Location 1'!P53 | H21: =(F21*G21) | I21: 1 | J21: =H21/I21
A22: 2 | B22: ='Location 2'!R1 | C22: 1 | D22: 1 | E22: 1 | F22: =C22*D22*E22 | G22: ='Location 2'!P55 | H22: =(F22*G22) | I22: 1 | J22: =H22/I22
A23: 3 | B23: ='Location 3'!R1 | C23: 1 | D23: 1 | E23: 1 | F23: =C23*D23*E23 | G23: ='Location 3'!P73 | H23: =(F23*G23) | I23: 1 | J23: =H23/I23
A24: 4 | B24: ='Location 4'!R1 | C24: 1 | D24: 1 | E24: 1 | F24: =C24*D24*E24 | G24: ='Location 4'!P73 | H24: =(F24*G24) | I24: 1 | J24: =H24/I24
A25: 5 | B25: ='Location 5'!R1 | C25: 1 | D25: 1 | E25: 1 | F25: =C25*D25*E25 | G25: ='Location 5'!P73 | H25: =(F25*G25) | I25: 1 | J25: =H25/I25
A26: 6 | B26: ='Location 6'!R1 | C26: 1 | D26: 1 | E26: 1 | F26: =C26*D26*E26 | G26: ='Location 6'!P73 | H26: =(F26*G26) | I26: 1 | J26: =H26/I26
A27: Subtotal Subcontractors | H27: =SUM(H21:H26) | J27: =SUM(J21:J26)
A28: Optional Work
A29: Item | B29: Material Item | C29: Surcharge | D29: Units | E29: Other | F29: Total Surcharge | G29: Unit Price | H29: Subtotal 1 | I29: Margin | J29: Subtotal 2
A30: 1 | B30: ='Option 1'!R1 | C30: 1 | D30: 1 | E30: 1 | F30: =C30*D30*E30 | G30: ='Option 1'!P73 | H30: =C30*D30*E30*F30*G30 | I30: 1 | J30: =H30/I30
F31: =C31*D31*E31 | H31: =C31*D31*E31*F31*G31 | I31: 1 | J31: =H31/I31
A32: Subtotal Materials and Equipment | H32: =SUM(H30:H31) | J32: =SUM(J30:J31)
A35: Project Subtotal | J35: =J18+J27
A37: Cash Allowance | J37: 0
A39: Utility Isolation | J39: 0
A41: Discount | J41: 0
A43: Project Options Subtotal | J43: =(J32)
A45: Project Total | J45: =J35+J37+J39+J41+J43
A46: HST | J46: =J45*0.13
A47: TOTAL | J47: =J45+J46
A48: HST Check for final price should be the same as above | J48: =J45*1.13
G52: Cost Analysis | J52: Price
...

Sheet Location 1
A1: {=MID(CELL("filename",C1),FIND("]",CELL("filename",C1))+1,255)} | R1: {=MID(CELL("filename",C1),FIND("]",CELL("filename",C1))+1,255)}
A3: AINSWORTH LABOUR
A4: Item | B4: Task | C4: Regular Labour Rates | I4: Premium Labour Rates | O4: Margin | P4: Subtotal 3 - Sell Rate
C5: # of techs | D5: Days/Units | E5: Regular Hours | F5: Total Regular Hours | G5: Regular Labour Rate | H5: Subtotal 1 | I5: # of techs | J5: Days/Units | K5: O/T Hours | L5: Total O/T Hours | M5: O/T Labour Rate | N5: Subtotal 2
A6: Project Management | T6: =(P26+P37+P42)*0.05
A7: 1 | B7: Engineering/Meetings | C7: 0 | D7: 0 | F7: =C7*D7*E7 | G7: 90 | H7: =F7*G7 | L7: =I7*J7*K7 | M7: 150 | N7: =L7*M7 | O7: 0.85 | P7: =H7/O7+N7/O7
A8: 2 | B8: Project Management | C8: 0 | D8: 1 | E8: 1 | F8: =C8*D8*E8 | G8: =(P26+P37+P42) | H8: =F8*G8 | L8: =I8*J8*K8 | M8: 150 | N8: =L8*M8 | O8: 0.85 | P8: =H8/O8+N8/O8
A9: 3 | B9: ESA Submissions | C9: 1 | D9: 1 | E9: 1 | F9: =C9*D9*E9 | G9: 250 | H9: =F9*G9 | L9: =I9*J9*K9 | M9: 0 | N9: =L9*M9 | O9: 0.85 | P9: =H9/O9+N9/O9
A10: 4 | B10: Misc. Subcontractors | C10: 0 | D10: 1 | E10: 1 | F10: =C10*D10*E10 | G10: =P37 | H10: =F10*G10 | L10: =I10*J10*K10 | M10: 150 | N10: =L10*M10 | O10: 0.85 | P10: =H10/O10+N10/O10
A11: 5 | B11: Misc. Materials | C11: 0 | D11: 1 | E11: 1 | F11: =C11*D11*E11 | G11: =P42 | H11: =F11*G11 | L11: =I11*J11*K11 | M11: 150 | N11: =L11*M11 | O11: 0.85 | P11: =H11/O11+N11/O11
A12: 6 | B12: Forman - site supervision and civil | F12: =C12*D12*E12 | G12: 92 | H12: =F12*G12 | L12: =I12*J12*K12 | M12: 150 | N12: =L12*M12 | O12: 0.85 | P12: =H12/O12+N12/O12
A13: 7 | B13: Lodging | C13: 1 | D13: 1 | E13: 1 | F13: =C13*D13*E13 | G13: 0 | H13: =F13*G13 | L13: =I13*J13*K13 | M13: 175 | N13: =L13*M13 | O13: 0.85 | P13: =H13/O13+N13/O13
A14: Total Management | F14: =SUM(F7:F13) | H14: =SUM(H7:H13) | L14: =SUM(L7:L13) | N14: =SUM(N7:N13) | P14: =SUM(P7:P13)
A16: Labour
A17: 1 | B17: Switching | F17: =C17*D17*E17 | G17: 108 | H17: =F17*G17 | L17: =I17*J17*K17 | M17: 195 | N17: =L17*M17 | O17: 0.85 | P17: =H17/O17+N17/O17
A18: 2 | B18: 16 kV Breakers: Four (4) Siemens vacuum type breakers M13-1, M13-3, M13-4 and M13-6 | F18: =C18*D18*E18 | G18: 108 | H18: =F18*G18 | L18: =I18*J18*K18 | M18: 195 | N18: =L18*M18 | O18: 0.85 | P18: =H18/O18+N18/O18
A19: 3 | B19: 2500 KVA transformer (CUB-T1) | F19: =C19*D19*E19 | G19: 108 | H19: =F19*G19 | L19: =I19*J19*K19 | M19: 195 | N19: =L19*M19 | O19: 0.85 | P19: =H19/O19+N19/O19
A20: 4 | B20: Switchgear CUB SWGR 600 Volt Cutler-Hammer Drawout Magnum Main | F20: =C20*D20*E20 | G20: 108 | H20: =F20*G20 | L20: =I20*J20*K20 | M20: 195 | N20: =L20*M20 | O20: 0.85 | P20: =H20/O20+N20/O20
A21: 5 | B21: 2500 KVA transformer (CUB-T2) | F21: =C21*D21*E21 | G21: 108 | H21: =F21*G21 | L21: =I21*J21*K21 | M21: 195 | N21: =L21*M21 | O21: 0.85 | P21: =H21/O21+N21/O21
A22: 6 | B22: 8200 KVA CUB Cogen transformer | F22: =C22*D22*E22 | G22: 108 | H22: =F22*G22 | L22: =I22*J22*K22 | M22: 195 | N22: =L22*M22 | O22: 0.85 | P22: =H22/O22+N22/O22
A23: 7 | B23: 5 kV Breakers: Four (4) Square vacuum type breakers | F23: =C23*D23*E23 | G23: 108 | H23: =F23*G23 | L23: =I23*J23*K23 | M23: 195 | N23: =L23*M23 | O23: 0.85 | P23: =H23/O23+N23/O23
A24: 8 | B24: 750 kVA Black Start transformer | F24: =C24*D24*E24 | G24: 108 | L24: =I24*J24*K24 | M24: 195
A25: 9 | B25: Pole Work | F25: =C25*D25*E25 | G25: 108 | H25: =F25*G25 | L25: =I25*J25*K25 | M25: 195 | N25: =L25*M25 | O25: 0.85 | P25: =H25/O25+N25/O25
A26: Sub Total Labour | F26: =SUM(F17:F25) | H26: =SUM(H17:H25) | L26: =SUM(L17:L25) | N26: =SUM(N17:N25) | P26: =SUM(P17:P25)
A27: Subtotal Labour | F27: =F14+F26 | H27: =H14+H26 | L27: =L14+L26 | N27: =N14+N26 | P27: =P14+P26
A28: Subcontractors
A29: Item | B29: Task | C29: Surcharge | E29: Days/Units | G29: Other | I29: Total Surcharge | K29: Unit Price | M29: Subtotal 1 | O29: Margin | P29: Subtotal 2
A30: 1 | B30: Alectra | C30: 1 | E30: 1 | G30: 1 | I30: =C30*E30*G30 | K30: 2000 | M30: =K30*I30 | O30: 0.9 | P30: =M30/O30
A31: 2 | B31: parking | I31: =C31*E31*G31 | M31: =K31*I31 | O31: 0.85 | P31: =M31/O31
A32: 3 | B32: Millwrighting | I32: =C32*E32*G32 | M32: =K32*I32 | O32: 0.85 | P32: =M32/O32
A33: 4 | B33: Temp Door | I33: =C33*E33*G33 | M33: =K33*I33 | O33: 0.85 | P33: =M33/O33
A34: 5 | B34: Bonding Costs | I34: =C34*E34*G34 | M34: =K34*I34 | O34: 0.85 | P34: =M34/O34
I35: =C35*E35*G35 | M35: =K35*I35 | O35: 0.85 | P35: =M35/O35
I36: =C36*E36*G36 | M36: =K36*I36 | O36: 0.85 | P36: =M36/O36
A37: Subtotal Subcontractors | P37: =SUM(P30:P36)
A38: Materials and Equipment
A39: Item | B39: Material Item | C39: Surcharge | E39: Units/Length | G39: Other | I39: Total Surcharge | K39: Unit Price | M39: Subtotal 1 | O39: Margin | P39: Subtotal 2
A40: 1 | B40: Batteries | C40: 1 | E40: 10 | G40: 1 | I40: =G40*E40*C40 | K40: 12 | M40: =K40*I40 | O40: 0.85 | P40: =M40/O40
A41: 2 | I41: =G41*E41*C41 | M41: =K41*I41 | O41: 0.85 | P41: =M41/O41
A42: Subtotal Materials and Equipment | P42: =SUM(P40:P41)
...

Sheet Location 2
A1: {=MID(CELL("filename",C1),FIND("]",CELL("filename",C1))+1,255)} | R1: {=MID(CELL("filename",C1),FIND("]",CELL("filename",C1))+1,255)}
A3: AINSWORTH LABOUR
A4: Item | B4: Task | C4: Regular Labour Rates | I4: Premium Labour Rates | O4: Margin | P4: Subtotal 3 - Sell Rate
C5: # of techs | D5: Days/Units | E5: Regular Hours | F5: Total Regular Hours | G5: Regular Labour Rate | H5: Subtotal 1 | I5: # of techs | J5: Days/Units | K5: O/T Hours | L5: Total O/T Hours | M5: O/T Labour Rate | N5: Subtotal 2
A6: Project Management | T6: =(P22+P33+P44)*0.05
A7: 1 | B7: Engineering/Meetings | C7: 0 | D7: 0 | F7: =C7*D7*E7 | G7: 90 | H7: =F7*G7 | L7: =I7*J7*K7 | M7: 150 | N7: =L7*M7 | O7: 0.85 | P7: =H7/O7+N7/O7
A8: 2 | B8: Project Management | C8: 0.05 | D8: 1 | E8: 1 | F8: =C8*D8*E8 | G8: =(P22+P33+P44) | H8: =F8*G8 | L8: =I8*J8*K8 | M8: 150 | N8: =L8*M8 | O8: 0.85 | P8: =H8/O8+N8/O8
A9: 3 | B9: ESA Submissions | F9: =C9*D9*E9 | G9: 2000 | H9: =F9*G9 | L9: =I9*J9*K9 | M9: 0 | N9: =L9*M9 | O9: 0.85 | P9: =H9/O9+N9/O9
A10: 4 | B10: Misc. Subcontractors | C10: 0.05 | D10: 1 | E10: 1 | F10: =C10*D10*E10 | G10: =P33 | H10: =F10*G10 | L10: =I10*J10*K10 | M10: 150 | N10: =L10*M10 | O10: 0.85 | P10: =H10/O10+N10/O10
A11: 5 | B11: Misc. Materials | C11: 0.05 | D11: 1 | E11: 1 | F11: =C11*D11*E11 | G11: =P44 | H11: =F11*G11 | L11: =I11*J11*K11 | M11: 150 | N11: =L11*M11 | O11: 0.85 | P11: =H11/O11+N11/O11
A12: 6 | B12: Forman - site supervision and civil | F12: =C12*D12*E12 | G12: 92 | H12: =F12*G12 | L12: =I12*J12*K12 | M12: 150 | N12: =L12*M12 | O12: 0.85 | P12: =H12/O12+N12/O12
A13: 7 | B13: Lodging | C13: 1 | D13: 1 | E13: 1 | F13: =C13*D13*E13 | G13: 0 | H13: =F13*G13 | L13: =I13*J13*K13 | M13: 175 | N13: =L13*M13 | O13: 0.85 | P13: =H13/O13+N13/O13
A14: Total Management | F14: =SUM(F7:F13) | H14: =SUM(H7:H13) | L14: =SUM(L7:L13) | N14: =SUM(N7:N13) | P14: =SUM(P7:P13)
A16: Labour
A17: 1 | B17: Mob/demob | F17: =C17*D17*E17 | G17: 108 | H17: =F17*G17 | L17: =I17*J17*K17 | M17: 195 | N17: =L17*M17 | O17: 0.85 | P17: =H17/O17+N17/O17
A18: 2 | B18: install | F18: =C18*D18*E18 | G18: 108 | H18: =F18*G18 | L18: =I18*J18*K18 | M18: 195 | N18: =L18*M18 | O18: 0.85 | P18: =H18/O18+N18/O18
A19: 3 | B19: assist | F19: =C19*D19*E19 | G19: 108 | H19: =F19*G19 | L19: =I19*J19*K19 | M19: 195 | N19: =L19*M19 | O19: 0.85 | P19: =H19/O19+N19/O19
A20: 4 | F20: =C20*D20*E20 | G20: 108 | H20: =F20*G20 | L20: =I20*J20*K20 | M20: 195 | N20: =L20*M20 | O20: 0.85 | P20: =H20/O20+N20/O20
A21: 9 | F21: =C21*D21*E21 | G21: 108 | H21: =F21*G21 | L21: =I21*J21*K21 | M21: 195 | N21: =L21*M21 | O21: 0.85 | P21: =H21/O21+N21/O21
A22: Sub Total Labour | F22: =SUM(F17:F21) | H22: =SUM(H17:H21) | L22: =SUM(L17:L21) | N22: =SUM(N17:N21) | P22: =SUM(P17:P21)
A23: Subtotal Labour | F23: =F14+F22 | H23: =H14+H22 | L23: =L14+L22 | N23: =N14+N22 | P23: =P14+P22
A24: Subcontractors
A25: Item | B25: Task | C25: Surcharge | E25: Days/Units | G25: Other | I25: Total Surcharge | K25: Unit Price | M25: Subtotal 1 | O25: Margin | P25: Subtotal 2
A26: 1 | B26: MG Power and Associates Inc | I26: =C26*E26*G26 | M26: =K26*I26 | O26: 0.85 | P26: =M26/O26
A27: 2 | B27: parking | I27: =C27*E27*G27 | M27: =K27*I27 | O27: 0.85 | P27: =M27/O27
A28: 3 | B28: Millwrighting | I28: =C28*E28*G28 | M28: =K28*I28 | O28: 0.85 | P28: =M28/O28
A29: 4 | B29: Temp Door | I29: =C29*E29*G29 | M29: =K29*I29 | O29: 0.85 | P29: =M29/O29
A30: 5 | B30: Bonding Costs | I30: =C30*E30*G30 | M30: =K30*I30 | O30: 0.85 | P30: =M30/O30
I31: =C31*E31*G31 | M31: =K31*I31 | O31: 0.85 | P31: =M31/O31
I32: =C32*E32*G32 | M32: =K32*I32 | O32: 0.85 | P32: =M32/O32
A33: Subtotal Subcontractors | P33: =SUM(P26:P32)
A34: Materials and Equipment
A35: Item | B35: Material Item | C35: Surcharge | E35: Units/Length | G35: Other | I35: Total Surcharge | K35: Unit Price | M35: Subtotal 1 | O35: Margin | P35: Subtotal 2
A36: 1 | B36: ABB SWGR | I36: =G36*E36*C36 | M36: =K36*I36 | O36: 0.85 | P36: =M36/O36
A37: 2 | B37: parking | I37: =G37*E37*C37 | M37: =K37*I37 | O37: 0.85 | P37: =M37/O37
A38: 18 | B38: AS-7096N Sealant | I38: =G38*E38*C38 | M38: =K38*I38 | O38: 0.85 | P38: =M38/O38
A39: 19 | B39: Breaker HLL36060 | I39: =G39*E39*C39 | M39: =K39*I39 | O39: 0.85 | P39: =M39/O39
A40: 20 | B40: Pull Box, EEMAC-1 300mX300mmX150mm (P/N: CS12126) | I40: =G40*E40*C40 | M40: =K40*I40 | O40: 0.85 | P40: =M40/O40
A41: 27 | B41: Aluminum Bracket (Aluma Form) | I41: =G41*E41*C41 | M41: =K41*I41 | O41: 0.85 | P41: =M41/O41
A42: 28 | I42: =G42*E42*C42 | M42: =K42*I42 | O42: 0.85 | P42: =M42/O42
...

Sheet Location 3
A1: {=MID(CELL("filename",C1),FIND("]",CELL("filename",C1))+1,255)} | R1: {=MID(CELL("filename",C1),FIND("]",CELL("filename",C1))+1,255)}
A3: AINSWORTH LABOUR
A4: Item | B4: Task | C4: Regular Labour Rates | I4: Premium Labour Rates | O4: Margin | P4: Subtotal 3 - Sell Rate
C5: # of techs | D5: Days/Units | E5: Regular Hours | F5: Total Regular Hours | G5: Regular Labour Rate | H5: Subtotal 1 | I5: # of techs | J5: Days/Units | K5: O/T Hours | L5: Total O/T Hours | M5: O/T Labour Rate | N5: Subtotal 2
A6: Project Management | T6: =(P25+P36+P62)*0.05
A7: 1 | B7: Engineering/Meetings | C7: 0 | D7: 0 | F7: =C7*D7*E7 | G7: 90 | H7: =F7*G7 | L7: =I7*J7*K7 | M7: 150 | N7: =L7*M7 | O7: 0.85 | P7: =H7/O7+N7/O7
A8: 2 | B8: Project Management | C8: 0.05 | D8: 1 | E8: 1 | F8: =C8*D8*E8 | G8: =(P25+P36+P62) | H8: =F8*G8 | L8: =I8*J8*K8 | M8: 150 | N8: =L8*M8 | O8: 0.85 | P8: =H8/O8+N8/O8
A9: 3 | B9: ESA Submissions | F9: =C9*D9*E9 | G9: 2000 | H9: =F9*G9 | L9: =I9*J9*K9 | M9: 0 | N9: =L9*M9 | O9: 0.85 | P9: =H9/O9+N9/O9
A10: 4 | B10: Misc. Subcontractors | C10: 0.05 | D10: 1 | E10: 1 | F10: =C10*D10*E10 | G10: =P36 | H10: =F10*G10 | L10: =I10*J10*K10 | M10: 150 | N10: =L10*M10 | O10: 0.85 | P10: =H10/O10+N10/O10
A11: 5 | B11: Misc. Materials | C11: 0.05 | D11: 1 | E11: 1 | F11: =C11*D11*E11 | G11: =P62 | H11: =F11*G11 | L11: =I11*J11*K11 | M11: 150 | N11: =L11*M11 | O11: 0.85 | P11: =H11/O11+N11/O11
A12: 6 | B12: Forman - site supervision and civil | F12: =C12*D12*E12 | G12: 92 | H12: =F12*G12 | L12: =I12*J12*K12 | M12: 150 | N12: =L12*M12 | O12: 0.85 | P12: =H12/O12+N12/O12
A13: 7 | B13: Lodging | C13: 1 | D13: 1 | E13: 1 | F13: =C13*D13*E13 | G13: 0 | H13: =F13*G13 | L13: =I13*J13*K13 | M13: 175 | N13: =L13*M13 | O13: 0.85 | P13: =H13/O13+N13/O13
A14: Total Management | F14: =SUM(F7:F13) | H14: =SUM(H7:H13) | L14: =SUM(L7:L13) | N14: =SUM(N7:N13) | P14: =SUM(P7:P13)
A16: Labour
A17: 1 | B17: Mob/demob | F17: =C17*D17*E17 | G17: 108 | H17: =F17*G17 | L17: =I17*J17*K17 | M17: 195 | N17: =L17*M17 | O17: 0.85 | P17: =H17/O17+N17/O17
A18: 2 | B18: install | F18: =C18*D18*E18 | G18: 108 | H18: =F18*G18 | L18: =I18*J18*K18 | M18: 195 | N18: =L18*M18 | O18: 0.85 | P18: =H18/O18+N18/O18
A19: 3 | B19: assist | F19: =C19*D19*E19 | G19: 108 | H19: =F19*G19 | L19: =I19*J19*K19 | M19: 195 | N19: =L19*M19 | O19: 0.85 | P19: =H19/O19+N19/O19
A20: 4 | F20: =C20*D20*E20 | G20: 108 | H20: =F20*G20 | L20: =I20*J20*K20 | M20: 195 | N20: =L20*M20 | O20: 0.85 | P20: =H20/O20+N20/O20
A21: 5 | F21: =C21*D21*E21 | G21: 108 | H21: =F21*G21 | L21: =I21*J21*K21 | M21: 195 | N21: =L21*M21 | O21: 0.85 | P21: =H21/O21+N21/O21
A22: 6 | F22: =C22*D22*E22 | G22: 108 | H22: =F22*G22 | L22: =I22*J22*K22 | M22: 195 | N22: =L22*M22 | O22: 0.85 | P22: =H22/O22+N22/O22
A23: 7 | F23: =C23*D23*E23 | G23: 108 | H23: =F23*G23 | L23: =I23*J23*K23 | M23: 195 | N23: =L23*M23 | O23: 0.85 | P23: =H23/O23+N23/O23
A24: 8 | F24: =C24*D24*E24 | G24: 108 | H24: =F24*G24 | L24: =I24*J24*K24 | M24: 195 | N24: =L24*M24 | O24: 0.85 | P24: =H24/O24+N24/O24
A25: Sub Total Labour | F25: =SUM(F17:F24) | H25: =SUM(H17:H24) | L25: =SUM(L17:L24) | N25: =SUM(N17:N24) | P25: =SUM(P17:P24)
A26: Subtotal Labour | F26: =F14+F25 | H26: =H14+H25 | L26: =L14+L25 | N26: =N14+N25 | P26: =P14+P25
A27: Subcontractors
A28: Item | B28: Task | C28: Surcharge | E28: Days/Units | G28: Other | I28: Total Surcharge | K28: Unit Price | M28: Subtotal 1 | O28: Margin | P28: Subtotal 2
A29: 1 | B29: MG Power and Associates Inc | I29: =C29*E29*G29 | M29: =K29*I29 | O29: 0.85 | P29: =M29/O29
A30: 2 | B30: parking | I30: =C30*E30*G30 | M30: =K30*I30 | O30: 0.85 | P30: =M30/O30
A31: 3 | B31: Millwrighting | I31: =C31*E31*G31 | M31: =K31*I31 | O31: 0.85 | P31: =M31/O31
A32: 4 | B32: Temp Door | I32: =C32*E32*G32 | M32: =K32*I32 | O32: 0.85 | P32: =M32/O32
A33: 5 | B33: Bonding Costs | I33: =C33*E33*G33 | M33: =K33*I33 | O33: 0.85 | P33: =M33/O33
I34: =C34*E34*G34 | M34: =K34*I34 | O34: 0.85 | P34: =M34/O34
I35: =C35*E35*G35 | M35: =K35*I35 | O35: 0.85 | P35: =M35/O35
A36: Subtotal Subcontractors | P36: =SUM(P29:P35)
A37: Materials and Equipment
A38: Item | B38: Material Item | C38: Surcharge | E38: Units/Length | G38: Other | I38: Total Surcharge | K38: Unit Price | M38: Subtotal 1 | O38: Margin | P38: Subtotal 2
A39: 1 | B39: ABB SWGR | I39: =G39*E39*C39 | M39: =K39*I39 | O39: 0.85 | P39: =M39/O39
A40: 2 | B40: parking | I40: =G40*E40*C40 | M40: =K40*I40 | O40: 0.85 | P40: =M40/O40
A41: 3 | I41: =G41*E41*C41 | M41: =K41*I41 | O41: 0.85 | P41: =M41/O41
A42: 4 | I42: =G42*E42*C42 | M42: =K42*I42 | O42: 0.85 | P42: =M42/O42
...

Sheet Location 4
A1: {=MID(CELL("filename",C1),FIND("]",CELL("filename",C1))+1,255)} | R1: {=MID(CELL("filename",C1),FIND("]",CELL("filename",C1))+1,255)}
A3: AINSWORTH LABOUR
A4: Item | B4: Task | C4: Regular Labour Rates | I4: Premium Labour Rates | O4: Margin | P4: Subtotal 3 - Sell Rate
C5: # of techs | D5: Days/Units | E5: Regular Hours | F5: Total Regular Hours | G5: Regular Labour Rate | H5: Subtotal 1 | I5: # of techs | J5: Days/Units | K5: O/T Hours | L5: Total O/T Hours | M5: O/T Labour Rate | N5: Subtotal 2
A6: Project Management | T6: =(P25+P36+P62)*0.05
A7: 1 | B7: Engineering/Meetings | C7: 0 | D7: 0 | F7: =C7*D7*E7 | G7: 90 | H7: =F7*G7 | L7: =I7*J7*K7 | M7: 150 | N7: =L7*M7 | O7: 0.85 | P7: =H7/O7+N7/O7
A8: 2 | B8: Project Management | C8: 0.05 | D8: 1 | E8: 1 | F8: =C8*D8*E8 | G8: =(P25+P36+P62) | H8: =F8*G8 | L8: =I8*J8*K8 | M8: 150 | N8: =L8*M8 | O8: 0.85 | P8: =H8/O8+N8/O8
A9: 3 | B9: ESA Submissions | F9: =C9*D9*E9 | G9: 2000 | H9: =F9*G9 | L9: =I9*J9*K9 | M9: 0 | N9: =L9*M9 | O9: 0.85 | P9: =H9/O9+N9/O9
A10: 4 | B10: Misc. Subcontractors | C10: 0.05 | D10: 1 | E10: 1 | F10: =C10*D10*E10 | G10: =P36 | H10: =F10*G10 | L10: =I10*J10*K10 | M10: 150 | N10: =L10*M10 | O10: 0.85 | P10: =H10/O10+N10/O10
A11: 5 | B11: Misc. Materials | C11: 0.05 | D11: 1 | E11: 1 | F11: =C11*D11*E11 | G11: =P62 | H11: =F11*G11 | L11: =I11*J11*K11 | M11: 150 | N11: =L11*M11 | O11: 0.85 | P11: =H11/O11+N11/O11
A12: 6 | B12: Forman - site supervision and civil | F12: =C12*D12*E12 | G12: 92 | H12: =F12*G12 | L12: =I12*J12*K12 | M12: 150 | N12: =L12*M12 | O12: 0.85 | P12: =H12/O12+N12/O12
A13: 7 | B13: Lodging | C13: 1 | D13: 1 | E13: 1 | F13: =C13*D13*E13 | G13: 0 | H13: =F13*G13 | L13: =I13*J13*K13 | M13: 175 | N13: =L13*M13 | O13: 0.85 | P13: =H13/O13+N13/O13
A14: Total Management | F14: =SUM(F7:F13) | H14: =SUM(H7:H13) | L14: =SUM(L7:L13) | N14: =SUM(N7:N13) | P14: =SUM(P7:P13)
A16: Labour
A17: 1 | B17: Mob/demob | F17: =C17*D17*E17 | G17: 108 | H17: =F17*G17 | L17: =I17*J17*K17 | M17: 195 | N17: =L17*M17 | O17: 0.85 | P17: =H17/O17+N17/O17
A18: 2 | B18: install | F18: =C18*D18*E18 | G18: 108 | H18: =F18*G18 | L18: =I18*J18*K18 | M18: 195 | N18: =L18*M18 | O18: 0.85 | P18: =H18/O18+N18/O18
A19: 3 | B19: assist | F19: =C19*D19*E19 | G19: 108 | H19: =F19*G19 | L19: =I19*J19*K19 | M19: 195 | N19: =L19*M19 | O19: 0.85 | P19: =H19/O19+N19/O19
A20: 4 | F20: =C20*D20*E20 | G20: 108 | H20: =F20*G20 | L20: =I20*J20*K20 | M20: 195 | N20: =L20*M20 | O20: 0.85 | P20: =H20/O20+N20/O20
A21: 5 | F21: =C21*D21*E21 | G21: 108 | H21: =F21*G21 | L21: =I21*J21*K21 | M21: 195 | N21: =L21*M21 | O21: 0.85 | P21: =H21/O21+N21/O21
A22: 6 | F22: =C22*D22*E22 | G22: 108 | H22: =F22*G22 | L22: =I22*J22*K22 | M22: 195 | N22: =L22*M22 | O22: 0.85 | P22: =H22/O22+N22/O22
A23: 7 | F23: =C23*D23*E23 | G23: 108 | H23: =F23*G23 | L23: =I23*J23*K23 | M23: 195 | N23: =L23*M23 | O23: 0.85 | P23: =H23/O23+N23/O23
A24: 8 | F24: =C24*D24*E24 | G24: 108 | H24: =F24*G24 | L24: =I24*J24*K24 | M24: 195 | N24: =L24*M24 | O24: 0.85 | P24: =H24/O24+N24/O24
A25: Sub Total Labour | F25: =SUM(F17:F24) | H25: =SUM(H17:H24) | L25: =SUM(L17:L24) | N25: =SUM(N17:N24) | P25: =SUM(P17:P24)
A26: Subtotal Labour | F26: =F14+F25 | H26: =H14+H25 | L26: =L14+L25 | N26: =N14+N25 | P26: =P14+P25
A27: Subcontractors
A28: Item | B28: Task | C28: Surcharge | E28: Days/Units | G28: Other | I28: Total Surcharge | K28: Unit Price | M28: Subtotal 1 | O28: Margin | P28: Subtotal 2
A29: 1 | B29: MG Power and Associates Inc | I29: =C29*E29*G29 | M29: =K29*I29 | O29: 0.85 | P29: =M29/O29
A30: 2 | B30: parking | I30: =C30*E30*G30 | M30: =K30*I30 | O30: 0.85 | P30: =M30/O30
A31: 3 | B31: Millwrighting | I31: =C31*E31*G31 | M31: =K31*I31 | O31: 0.85 | P31: =M31/O31
A32: 4 | B32: Temp Door | I32: =C32*E32*G32 | M32: =K32*I32 | O32: 0.85 | P32: =M32/O32
A33: 5 | B33: Bonding Costs | I33: =C33*E33*G33 | M33: =K33*I33 | O33: 0.85 | P33: =M33/O33
I34: =C34*E34*G34 | M34: =K34*I34 | O34: 0.85 | P34: =M34/O34
I35: =C35*E35*G35 | M35: =K35*I35 | O35: 0.85 | P35: =M35/O35
A36: Subtotal Subcontractors | P36: =SUM(P29:P35)
A37: Materials and Equipment
A38: Item | B38: Material Item | C38: Surcharge | E38: Units/Length | G38: Other | I38: Total Surcharge | K38: Unit Price | M38: Subtotal 1 | O38: Margin | P38: Subtotal 2
A39: 1 | B39: ABB SWGR | I39: =G39*E39*C39 | M39: =K39*I39 | O39: 0.85 | P39: =M39/O39
A40: 2 | B40: parking | I40: =G40*E40*C40 | M40: =K40*I40 | O40: 0.85 | P40: =M40/O40
A41: 3 | I41: =G41*E41*C41 | M41: =K41*I41 | O41: 0.85 | P41: =M41/O41
A42: 4 | I42: =G42*E42*C42 | M42: =K42*I42 | O42: 0.85 | P42: =M42/O42
...

Sheet Location 5
A1: {=MID(CELL("filename",C1),FIND("]",CELL("filename",C1))+1,255)} | R1: {=MID(CELL("filename",C1),FIND("]",CELL("filename",C1))+1,255)}
A3: AINSWORTH LABOUR
A4: Item | B4: Task | C4: Regular Labour Rates | I4: Premium Labour Rates | O4: Margin | P4: Subtotal 3 - Sell Rate
C5: # of techs | D5: Days/Units | E5: Regular Hours | F5: Total Regular Hours | G5: Regular Labour Rate | H5: Subtotal 1 | I5: # of techs | J5: Days/Units | K5: O/T Hours | L5: Total O/T Hours | M5: O/T Labour Rate | N5: Subtotal 2
A6: Project Management | T6: =(P25+P36+P62)*0.05
A7: 1 | B7: Engineering/Meetings | C7: 0 | D7: 0 | F7: =C7*D7*E7 | G7: 90 | H7: =F7*G7 | L7: =I7*J7*K7 | M7: 150 | N7: =L7*M7 | O7: 0.85 | P7: =H7/O7+N7/O7
A8: 2 | B8: Project Management | C8: 0.05 | D8: 1 | E8: 1 | F8: =C8*D8*E8 | G8: =(P25+P36+P62) | H8: =F8*G8 | L8: =I8*J8*K8 | M8: 150 | N8: =L8*M8 | O8: 0.85 | P8: =H8/O8+N8/O8
A9: 3 | B9: ESA Submissions | F9: =C9*D9*E9 | G9: 2000 | H9: =F9*G9 | L9: =I9*J9*K9 | M9: 0 | N9: =L9*M9 | O9: 0.85 | P9: =H9/O9+N9/O9
A10: 4 | B10: Misc. Subcontractors | C10: 0.05 | D10: 1 | E10: 1 | F10: =C10*D10*E10 | G10: =P36 | H10: =F10*G10 | L10: =I10*J10*K10 | M10: 150 | N10: =L10*M10 | O10: 0.85 | P10: =H10/O10+N10/O10
A11: 5 | B11: Misc. Materials | C11: 0.05 | D11: 1 | E11: 1 | F11: =C11*D11*E11 | G11: =P62 | H11: =F11*G11 | L11: =I11*J11*K11 | M11: 150 | N11: =L11*M11 | O11: 0.85 | P11: =H11/O11+N11/O11
A12: 6 | B12: Forman - site supervision and civil | F12: =C12*D12*E12 | G12: 92 | H12: =F12*G12 | L12: =I12*J12*K12 | M12: 150 | N12: =L12*M12 | O12: 0.85 | P12: =H12/O12+N12/O12
A13: 7 | B13: Lodging | C13: 1 | D13: 1 | E13: 1 | F13: =C13*D13*E13 | G13: 0 | H13: =F13*G13 | L13: =I13*J13*K13 | M13: 175 | N13: =L13*M13 | O13: 0.85 | P13: =H13/O13+N13/O13
A14: Total Management | F14: =SUM(F7:F13) | H14: =SUM(H7:H13) | L14: =SUM(L7:L13) | N14: =SUM(N7:N13) | P14: =SUM(P7:P13)
A16: Labour
A17: 1 | B17: Mob/demob | F17: =C17*D17*E17 | G17: 108 | H17: =F17*G17 | L17: =I17*J17*K17 | M17: 195 | N17: =L17*M17 | O17: 0.85 | P17: =H17/O17+N17/O17
A18: 2 | B18: install | F18: =C18*D18*E18 | G18: 108 | H18: =F18*G18 | L18: =I18*J18*K18 | M18: 195 | N18: =L18*M18 | O18: 0.85 | P18: =H18/O18+N18/O18
A19: 3 | B19: assist | F19: =C19*D19*E19 | G19: 108 | H19: =F19*G19 | L19: =I19*J19*K19 | M19: 195 | N19: =L19*M19 | O19: 0.85 | P19: =H19/O19+N19/O19
A20: 4 | F20: =C20*D20*E20 | G20: 108 | H20: =F20*G20 | L20: =I20*J20*K20 | M20: 195 | N20: =L20*M20 | O20: 0.85 | P20: =H20/O20+N20/O20
A21: 5 | F21: =C21*D21*E21 | G21: 108 | H21: =F21*G21 | L21: =I21*J21*K21 | M21: 195 | N21: =L21*M21 | O21: 0.85 | P21: =H21/O21+N21/O21
A22: 6 | F22: =C22*D22*E22 | G22: 108 | H22: =F22*G22 | L22: =I22*J22*K22 | M22: 195 | N22: =L22*M22 | O22: 0.85 | P22: =H22/O22+N22/O22
A23: 7 | F23: =C23*D23*E23 | G23: 108 | H23: =F23*G23 | L23: =I23*J23*K23 | M23: 195 | N23: =L23*M23 | O23: 0.85 | P23: =H23/O23+N23/O23
A24: 8 | F24: =C24*D24*E24 | G24: 108 | H24: =F24*G24 | L24: =I24*J24*K24 | M24: 195 | N24: =L24*M24 | O24: 0.85 | P24: =H24/O24+N24/O24
A25: Sub Total Labour | F25: =SUM(F17:F24) | H25: =SUM(H17:H24) | L25: =SUM(L17:L24) | N25: =SUM(N17:N24) | P25: =SUM(P17:P24)
A26: Subtotal Labour | F26: =F14+F25 | H26: =H14+H25 | L26: =L14+L25 | N26: =N14+N25 | P26: =P14+P25
A27: Subcontractors
A28: Item | B28: Task | C28: Surcharge | E28: Days/Units | G28: Other | I28: Total Surcharge | K28: Unit Price | M28: Subtotal 1 | O28: Margin | P28: Subtotal 2
A29: 1 | B29: MG Power and Associates Inc | I29: =C29*E29*G29 | M29: =K29*I29 | O29: 0.85 | P29: =M29/O29
A30: 2 | B30: parking | I30: =C30*E30*G30 | M30: =K30*I30 | O30: 0.85 | P30: =M30/O30
A31: 3 | B31: Millwrighting | I31: =C31*E31*G31 | M31: =K31*I31 | O31: 0.85 | P31: =M31/O31
A32: 4 | B32: Temp Door | I32: =C32*E32*G32 | M32: =K32*I32 | O32: 0.85 | P32: =M32/O32
A33: 5 | B33: Bonding Costs | I33: =C33*E33*G33 | M33: =K33*I33 | O33: 0.85 | P33: =M33/O33
I34: =C34*E34*G34 | M34: =K34*I34 | O34: 0.85 | P34: =M34/O34
I35: =C35*E35*G35 | M35: =K35*I35 | O35: 0.85 | P35: =M35/O35
A36: Subtotal Subcontractors | P36: =SUM(P29:P35)
A37: Materials and Equipment
A38: Item | B38: Material Item | C38: Surcharge | E38: Units/Length | G38: Other | I38: Total Surcharge | K38: Unit Price | M38: Subtotal 1 | O38: Margin | P38: Subtotal 2
A39: 1 | B39: ABB SWGR | I39: =G39*E39*C39 | M39: =K39*I39 | O39: 0.85 | P39: =M39/O39
A40: 2 | B40: parking | I40: =G40*E40*C40 | M40: =K40*I40 | O40: 0.85 | P40: =M40/O40
A41: 3 | I41: =G41*E41*C41 | M41: =K41*I41 | O41: 0.85 | P41: =M41/O41
A42: 4 | I42: =G42*E42*C42 | M42: =K42*I42 | O42: 0.85 | P42: =M42/O42
...

Sheet Location 6
A1: {=MID(CELL("filename",C1),FIND("]",CELL("filename",C1))+1,255)} | R1: {=MID(CELL("filename",C1),FIND("]",CELL("filename",C1))+1,255)}
A3: AINSWORTH LABOUR
A4: Item | B4: Task | C4: Regular Labour Rates | I4: Premium Labour Rates | O4: Margin | P4: Subtotal 3 - Sell Rate
C5: # of techs | D5: Days/Units | E5: Regular Hours | F5: Total Regular Hours | G5: Regular Labour Rate | H5: Subtotal 1 | I5: # of techs | J5: Days/Units | K5: O/T Hours | L5: Total O/T Hours | M5: O/T Labour Rate | N5: Subtotal 2
A6: Project Management | T6: =(P25+P36+P62)*0.05
A7: 1 | B7: Engineering/Meetings | C7: 0 | D7: 0 | F7: =C7*D7*E7 | G7: 90 | H7: =F7*G7 | L7: =I7*J7*K7 | M7: 150 | N7: =L7*M7 | O7: 0.85 | P7: =H7/O7+N7/O7
A8: 2 | B8: Project Management | C8: 0.05 | D8: 1 | E8: 1 | F8: =C8*D8*E8 | G8: =(P25+P36+P62) | H8: =F8*G8 | L8: =I8*J8*K8 | M8: 150 | N8: =L8*M8 | O8: 0.85 | P8: =H8/O8+N8/O8
A9: 3 | B9: ESA Submissions | F9: =C9*D9*E9 | G9: 2000 | H9: =F9*G9 | L9: =I9*J9*K9 | M9: 0 | N9: =L9*M9 | O9: 0.85 | P9: =H9/O9+N9/O9
A10: 4 | B10: Misc. Subcontractors | C10: 0.05 | D10: 1 | E10: 1 | F10: =C10*D10*E10 | G10: =P36 | H10: =F10*G10 | L10: =I10*J10*K10 | M10: 150 | N10: =L10*M10 | O10: 0.85 | P10: =H10/O10+N10/O10
A11: 5 | B11: Misc. Materials | C11: 0.05 | D11: 1 | E11: 1 | F11: =C11*D11*E11 | G11: =P62 | H11: =F11*G11 | L11: =I11*J11*K11 | M11: 150 | N11: =L11*M11 | O11: 0.85 | P11: =H11/O11+N11/O11
A12: 6 | B12: Forman - site supervision and civil | F12: =C12*D12*E12 | G12: 92 | H12: =F12*G12 | L12: =I12*J12*K12 | M12: 150 | N12: =L12*M12 | O12: 0.85 | P12: =H12/O12+N12/O12
A13: 7 | B13: Lodging | C13: 1 | D13: 1 | E13: 1 | F13: =C13*D13*E13 | G13: 0 | H13: =F13*G13 | L13: =I13*J13*K13 | M13: 175 | N13: =L13*M13 | O13: 0.85 | P13: =H13/O13+N13/O13
A14: Total Management | F14: =SUM(F7:F13) | H14: =SUM(H7:H13) | L14: =SUM(L7:L13) | N14: =SUM(N7:N13) | P14: =SUM(P7:P13)
A16: Labour
A17: 1 | B17: Mob/demob | F17: =C17*D17*E17 | G17: 108 | H17: =F17*G17 | L17: =I17*J17*K17 | M17: 195 | N17: =L17*M17 | O17: 0.85 | P17: =H17/O17+N17/O17
A18: 2 | B18: install | F18: =C18*D18*E18 | G18: 108 | H18: =F18*G18 | L18: =I18*J18*K18 | M18: 195 | N18: =L18*M18 | O18: 0.85 | P18: =H18/O18+N18/O18
A19: 3 | B19: assist | F19: =C19*D19*E19 | G19: 108 | H19: =F19*G19 | L19: =I19*J19*K19 | M19: 195 | N19: =L19*M19 | O19: 0.85 | P19: =H19/O19+N19/O19
A20: 4 | F20: =C20*D20*E20 | G20: 108 | H20: =F20*G20 | L20: =I20*J20*K20 | M20: 195 | N20: =L20*M20 | O20: 0.85 | P20: =H20/O20+N20/O20
A21: 5 | F21: =C21*D21*E21 | G21: 108 | H21: =F21*G21 | L21: =I21*J21*K21 | M21: 195 | N21: =L21*M21 | O21: 0.85 | P21: =H21/O21+N21/O21
A22: 6 | F22: =C22*D22*E22 | G22: 108 | H22: =F22*G22 | L22: =I22*J22*K22 | M22: 195 | N22: =L22*M22 | O22: 0.85 | P22: =H22/O22+N22/O22
A23: 7 | F23: =C23*D23*E23 | G23: 108 | H23: =F23*G23 | L23: =I23*J23*K23 | M23: 195 | N23: =L23*M23 | O23: 0.85 | P23: =H23/O23+N23/O23
A24: 8 | F24: =C24*D24*E24 | G24: 108 | H24: =F24*G24 | L24: =I24*J24*K24 | M24: 195 | N24: =L24*M24 | O24: 0.85 | P24: =H24/O24+N24/O24
A25: Sub Total Labour | F25: =SUM(F17:F24) | H25: =SUM(H17:H24) | L25: =SUM(L17:L24) | N25: =SUM(N17:N24) | P25: =SUM(P17:P24)
A26: Subtotal Labour | F26: =F14+F25 | H26: =H14+H25 | L26: =L14+L25 | N26: =N14+N25 | P26: =P14+P25
A27: Subcontractors
A28: Item | B28: Task | C28: Surcharge | E28: Days/Units | G28: Other | I28: Total Surcharge | K28: Unit Price | M28: Subtotal 1 | O28: Margin | P28: Subtotal 2
A29: 1 | B29: MG Power and Associates Inc | I29: =C29*E29*G29 | M29: =K29*I29 | O29: 0.85 | P29: =M29/O29
A30: 2 | B30: parking | I30: =C30*E30*G30 | M30: =K30*I30 | O30: 0.85 | P30: =M30/O30
A31: 3 | B31: Millwrighting | I31: =C31*E31*G31 | M31: =K31*I31 | O31: 0.85 | P31: =M31/O31
A32: 4 | B32: Temp Door | I32: =C32*E32*G32 | M32: =K32*I32 | O32: 0.85 | P32: =M32/O32
A33: 5 | B33: Bonding Costs | I33: =C33*E33*G33 | M33: =K33*I33 | O33: 0.85 | P33: =M33/O33
I34: =C34*E34*G34 | M34: =K34*I34 | O34: 0.85 | P34: =M34/O34
I35: =C35*E35*G35 | M35: =K35*I35 | O35: 0.85 | P35: =M35/O35
A36: Subtotal Subcontractors | P36: =SUM(P29:P35)
A37: Materials and Equipment
A38: Item | B38: Material Item | C38: Surcharge | E38: Units/Length | G38: Other | I38: Total Surcharge | K38: Unit Price | M38: Subtotal 1 | O38: Margin | P38: Subtotal 2
A39: 1 | B39: ABB SWGR | I39: =G39*E39*C39 | M39: =K39*I39 | O39: 0.85 | P39: =M39/O39
A40: 2 | B40: parking | I40: =G40*E40*C40 | M40: =K40*I40 | O40: 0.85 | P40: =M40/O40
A41: 3 | I41: =G41*E41*C41 | M41: =K41*I41 | O41: 0.85 | P41: =M41/O41
A42: 4 | I42: =G42*E42*C42 | M42: =K42*I42 | O42: 0.85 | P42: =M42/O42
...

Sheet Option 1
A1: {=MID(CELL("filename",C1),FIND("]",CELL("filename",C1))+1,255)} | R1: {=MID(CELL("filename",C1),FIND("]",CELL("filename",C1))+1,255)}
A3: AINSWORTH LABOUR
A4: Item | B4: Task | C4: Regular Labour Rates | I4: Premium Labour Rates | O4: Margin | P4: Subtotal 3 - Sell Rate
C5: # of techs | D5: Days/Units | E5: Regular Hours | F5: Total Regular Hours | G5: Regular Labour Rate | H5: Subtotal 1 | I5: # of techs | J5: Days/Units | K5: O/T Hours | L5: Total O/T Hours | M5: O/T Labour Rate | N5: Subtotal 2
A6: Project Management | T6: =(P25+P36+P62)*0.05
A7: 1 | B7: Engineering/Meetings | C7: 0 | D7: 0 | F7: =C7*D7*E7 | G7: 90 | H7: =F7*G7 | L7: =I7*J7*K7 | M7: 150 | N7: =L7*M7 | O7: 0.85 | P7: =H7/O7+N7/O7
A8: 2 | B8: Project Management | C8: 0.05 | D8: 1 | E8: 1 | F8: =C8*D8*E8 | G8: =(P25+P36+P62) | H8: =F8*G8 | L8: =I8*J8*K8 | M8: 150 | N8: =L8*M8 | O8: 0.85 | P8: =H8/O8+N8/O8
A9: 3 | B9: ESA Submissions | F9: =C9*D9*E9 | G9: 2000 | H9: =F9*G9 | L9: =I9*J9*K9 | M9: 0 | N9: =L9*M9 | O9: 0.85 | P9: =H9/O9+N9/O9
A10: 4 | B10: Misc. Subcontractors | C10: 0.05 | D10: 1 | E10: 1 | F10: =C10*D10*E10 | G10: =P36 | H10: =F10*G10 | L10: =I10*J10*K10 | M10: 150 | N10: =L10*M10 | O10: 0.85 | P10: =H10/O10+N10/O10
A11: 5 | B11: Misc. Materials | C11: 0.05 | D11: 1 | E11: 1 | F11: =C11*D11*E11 | G11: =P62 | H11: =F11*G11 | L11: =I11*J11*K11 | M11: 150 | N11: =L11*M11 | O11: 0.85 | P11: =H11/O11+N11/O11
A12: 6 | B12: Forman - site supervision and civil | F12: =C12*D12*E12 | G12: 92 | H12: =F12*G12 | L12: =I12*J12*K12 | M12: 150 | N12: =L12*M12 | O12: 0.85 | P12: =H12/O12+N12/O12
A13: 7 | B13: Lodging | C13: 1 | D13: 1 | E13: 1 | F13: =C13*D13*E13 | G13: 0 | H13: =F13*G13 | L13: =I13*J13*K13 | M13: 175 | N13: =L13*M13 | O13: 0.85 | P13: =H13/O13+N13/O13
A14: Total Management | F14: =SUM(F7:F13) | H14: =SUM(H7:H13) | L14: =SUM(L7:L13) | N14: =SUM(N7:N13) | P14: =SUM(P7:P13)
A16: Labour
A17: 1 | B17: Mob/demob | F17: =C17*D17*E17 | G17: 108 | H17: =F17*G17 | L17: =I17*J17*K17 | M17: 195 | N17: =L17*M17 | O17: 0.85 | P17: =H17/O17+N17/O17
A18: 2 | B18: install | F18: =C18*D18*E18 | G18: 108 | H18: =F18*G18 | L18: =I18*J18*K18 | M18: 195 | N18: =L18*M18 | O18: 0.85 | P18: =H18/O18+N18/O18
A19: 3 | B19: assist | F19: =C19*D19*E19 | G19: 108 | H19: =F19*G19 | L19: =I19*J19*K19 | M19: 195 | N19: =L19*M19 | O19: 0.85 | P19: =H19/O19+N19/O19
A20: 4 | F20: =C20*D20*E20 | G20: 108 | H20: =F20*G20 | L20: =I20*J20*K20 | M20: 195 | N20: =L20*M20 | O20: 0.85 | P20: =H20/O20+N20/O20
A21: 5 | F21: =C21*D21*E21 | G21: 108 | H21: =F21*G21 | L21: =I21*J21*K21 | M21: 195 | N21: =L21*M21 | O21: 0.85 | P21: =H21/O21+N21/O21
A22: 6 | F22: =C22*D22*E22 | G22: 108 | H22: =F22*G22 | L22: =I22*J22*K22 | M22: 195 | N22: =L22*M22 | O22: 0.85 | P22: =H22/O22+N22/O22
A23: 7 | F23: =C23*D23*E23 | G23: 108 | H23: =F23*G23 | L23: =I23*J23*K23 | M23: 195 | N23: =L23*M23 | O23: 0.85 | P23: =H23/O23+N23/O23
A24: 8 | F24: =C24*D24*E24 | G24: 108 | H24: =F24*G24 | L24: =I24*J24*K24 | M24: 195 | N24: =L24*M24 | O24: 0.85 | P24: =H24/O24+N24/O24
A25: Sub Total Labour | F25: =SUM(F17:F24) | H25: =SUM(H17:H24) | L25: =SUM(L17:L24) | N25: =SUM(N17:N24) | P25: =SUM(P17:P24)
A26: Subtotal Labour | F26: =F14+F25 | H26: =H14+H25 | L26: =L14+L25 | N26: =N14+N25 | P26: =P14+P25
A27: Subcontractors
A28: Item | B28: Task | C28: Surcharge | E28: Days/Units | G28: Other | I28: Total Surcharge | K28: Unit Price | M28: Subtotal 1 | O28: Margin | P28: Subtotal 2
A29: 1 | B29: MG Power and Associates Inc | I29: =C29*E29*G29 | M29: =K29*I29 | O29: 0.85 | P29: =M29/O29
A30: 2 | B30: parking | I30: =C30*E30*G30 | M30: =K30*I30 | O30: 0.85 | P30: =M30/O30
A31: 3 | B31: Millwrighting | I31: =C31*E31*G31 | M31: =K31*I31 | O31: 0.85 | P31: =M31/O31
A32: 4 | B32: Temp Door | I32: =C32*E32*G32 | M32: =K32*I32 | O32: 0.85 | P32: =M32/O32
A33: 5 | B33: Bonding Costs | I33: =C33*E33*G33 | M33: =K33*I33 | O33: 0.85 | P33: =M33/O33
I34: =C34*E34*G34 | M34: =K34*I34 | O34: 0.85 | P34: =M34/O34
I35: =C35*E35*G35 | M35: =K35*I35 | O35: 0.85 | P35: =M35/O35
A36: Subtotal Subcontractors | P36: =SUM(P29:P35)
A37: Materials and Equipment
A38: Item | B38: Material Item | C38: Surcharge | E38: Units/Length | G38: Other | I38: Total Surcharge | K38: Unit Price | M38: Subtotal 1 | O38: Margin | P38: Subtotal 2
A39: 1 | B39: ABB SWGR | I39: =G39*E39*C39 | M39: =K39*I39 | O39: 0.85 | P39: =M39/O39
A40: 2 | B40: parking | I40: =G40*E40*C40 | M40: =K40*I40 | O40: 0.85 | P40: =M40/O40
A41: 3 | I41: =G41*E41*C41 | M41: =K41*I41 | O41: 0.85 | P41: =M41/O41
A42: 4 | I42: =G42*E42*C42 | M42: =K42*I42 | O42: 0.85 | P42: =M42/O42
...
